<?xml version="1.0" ?>
<robot name="myArm">
  <joint name="myArm__Gross_Bodenplatte" type="revolute">
    <parent link="myArm__Bodenplatte"/>
    <child link="myArm__GrossesGelenk1"/>
    <origin rpy="0  0  0" xyz="-0.1105   0      -0.12974"/>
    <axis xyz="0  0  1"/>
    <limit effort="-1.0" lower="-1.79769e+308" upper="1.79769e+308" velocity="-1.0"/>
  </joint>
  <joint name="myArm__Gross_Unterschwinge" type="fixed">
    <parent link="myArm__GrossesGelenk2"/>
    <child link="myArm__Unterschwinge"/>
    <origin rpy="0  0  0" xyz="0      -0.00584  0.3689"/>
    <axis xyz="0  0  0"/>
    <limit effort="0" lower="0" upper="0" velocity="0"/>
  </joint>
  <joint name="myArm__GrossesGelenkLink" type="revolute">
    <parent link="myArm__GrossesGelenk1"/>
    <child link="myArm__GrossesGelenk2"/>
    <origin rpy="0  0  0" xyz="0.21935  0       0"/>
    <axis xyz="1  0  0"/>
    <limit effort="-1.0" lower="-1.79769e+308" upper="1.79769e+308" velocity="-1.0"/>
  </joint>
  <joint name="myArm__Hand_LinkerFinger" type="fixed">
    <parent link="myArm__palm"/>
    <child link="myArm__left_finger"/>
    <origin rpy="0  0  0" xyz="0    -0.074 -0.061"/>
    <axis xyz="0  0  0"/>
    <limit effort="0" lower="0" upper="0" velocity="0"/>
  </joint>
  <joint name="myArm__Hand_RechterFinger" type="prismatic">
    <parent link="myArm__palm"/>
    <child link="myArm__right_finger"/>
    <origin rpy="0  0  0" xyz="0     0.07  -0.061"/>
    <axis xyz="0 -1  0"/>
    <limit effort="-1.0" lower="0.0" upper="0.13" velocity="-1.0"/>
  </joint>
  <joint name="myArm__KleinesGelenkLink" type="revolute">
    <parent link="myArm__KleinesGelenk1"/>
    <child link="myArm__KleinesGelenk2"/>
    <origin rpy="0     -1.5707  0" xyz="0.00399  0       0.08414"/>
    <axis xyz="1  0  0"/>
    <limit effort="-1.0" lower="-1.79769e+308" upper="1.79769e+308" velocity="-1.0"/>
  </joint>
  <joint name="myArm__KleinesGelenk_Hand" type="fixed">
    <parent link="myArm__KleinesGelenk2"/>
    <child link="myArm__palm"/>
    <origin rpy="0  0  0" xyz="0.04967  0.00074 -0.12363"/>
    <axis xyz="0  0  0"/>
    <limit effort="0" lower="0" upper="0" velocity="0"/>
  </joint>
  <joint name="myArm__Mittel_Oberschwinge" type="revolute">
    <parent link="myArm__MittleresGelenk1"/>
    <child link="myArm__Oberschwinge"/>
    <origin rpy="-0.00073 -0.00538  0.01165" xyz="-1.70000000e-03   2.10000000e-04   3.16240000e-01"/>
    <axis xyz="0  0  1"/>
    <limit effort="-1.0" lower="-1.79769e+308" upper="1.79769e+308" velocity="-1.0"/>
  </joint>
  <joint name="myArm__MittleresGelenkLink" type="revolute">
    <parent link="myArm__MittleresGelenk2"/>
    <child link="myArm__MittleresGelenk1"/>
    <origin rpy="3.14159 -1.57079  3.14159" xyz="0.00117 -0.00252 -0.15624"/>
    <axis xyz="0.99991  0.01165  0.00538"/>
    <limit effort="-1.0" lower="-1.79769e+308" upper="1.79769e+308" velocity="-1.0"/>
  </joint>
  <joint name="myArm__Oberschwinge_KleinesGelenk" type="fixed">
    <parent link="myArm__Oberschwinge"/>
    <child link="myArm__KleinesGelenk1"/>
    <origin rpy="0      1.5707  0" xyz="0       0       0.29474"/>
    <axis xyz="0  0  0"/>
    <limit effort="0" lower="0" upper="0" velocity="0"/>
  </joint>
  <joint name="myArm__Unterschwinge_Mittel" type="fixed">
    <parent link="myArm__Unterschwinge"/>
    <child link="myArm__MittleresGelenk2"/>
    <origin rpy="3.01682  1.56535  3.00517" xyz="2.60000000e-04   5.80000000e-03   3.37780000e-01"/>
    <axis xyz="0  0  0"/>
    <limit effort="0" lower="0" upper="0" velocity="0"/>
  </joint>
  <link name="myArm__Bodenplatte">
    <inertial>
      <mass value="10000"/>
      <origin rpy="0  0  0" xyz="0  0  0"/>
      <inertia ixx="836.333" ixy="0" ixz="0" iyy="836.333" iyz="0" izz="1666.67"/>
    </inertial>
    <collision name="myArm__collision">
      <origin rpy="0  0  0" xyz="-0.1105   0      -0.26727"/>
      <geometry>
        <box size="0.2 0.1 0.055"/>
      </geometry>
    </collision>
    <visual name="myArm__visual">
      <origin rpy="0  0  0" xyz="-0.1105   0      -0.26727"/>
      <geometry>
        <box size="0.2 0.1 0.055"/>
      </geometry>
    </visual>
  </link>
  <link name="myArm__GrossesGelenk1">
    <inertial>
      <mass value="13"/>
      <origin rpy="0  0  0" xyz="0  0  0"/>
      <inertia ixx="1.89583" ixy="0" ixz="0" iyy="1.89583" iyz="0" izz="1.625"/>
    </inertial>
    <collision name="myArm__collision">
      <origin rpy="2.44361  1.57078  2.44361" xyz="0  0  0"/>
      <geometry>
        <cylinder length="0.215" radius="0.0975"/>
      </geometry>
    </collision>
    <visual name="myArm__visual">
      <origin rpy="2.44361  1.57078  2.44361" xyz="0  0  0"/>
      <geometry>
        <cylinder length="0.215" radius="0.0975"/>
      </geometry>
    </visual>
  </link>
  <link name="myArm__GrossesGelenk2">
    <inertial>
      <mass value="13"/>
      <origin rpy="0  0  0" xyz="0  0  0"/>
      <inertia ixx="1.89583" ixy="0" ixz="0" iyy="1.89583" iyz="0" izz="1.625"/>
    </inertial>
    <collision name="myArm__collision">
      <origin rpy="2.44361  1.57078  2.44361" xyz="0  0  0"/>
      <geometry>
        <cylinder length="0.215" radius="0.0975"/>
      </geometry>
    </collision>
    <visual name="myArm__visual">
      <origin rpy="2.44361  1.57078  2.44361" xyz="0  0  0"/>
      <geometry>
        <cylinder length="0.215" radius="0.0975"/>
      </geometry>
    </visual>
  </link>
  <link name="myArm__KleinesGelenk1">
    <inertial>
      <mass value="2.754"/>
      <origin rpy="0  0  0" xyz="0  0  0"/>
      <inertia ixx="0.145833" ixy="0" ixz="0" iyy="0.145833" iyz="0" izz="0.125"/>
    </inertial>
    <collision name="myArm__collision">
      <origin rpy="0  0  0" xyz="0  0  0"/>
      <geometry>
        <cylinder length="0.158" radius="0.045"/>
      </geometry>
    </collision>
    <visual name="myArm__visual">
      <origin rpy="0  0  0" xyz="0  0  0"/>
      <geometry>
        <cylinder length="0.158" radius="0.045"/>
      </geometry>
    </visual>
  </link>
  <link name="myArm__KleinesGelenk2">
    <inertial>
      <mass value="2.754"/>
      <origin rpy="0  0  0" xyz="0  0  0"/>
      <inertia ixx="0.145833" ixy="0" ixz="0" iyy="0.145833" iyz="0" izz="0.125"/>
    </inertial>
    <collision name="myArm__collision">
      <origin rpy="0  0  0" xyz="0.048  0    -0.03"/>
      <geometry>
        <cylinder length="0.158" radius="0.045"/>
      </geometry>
    </collision>
    <visual name="myArm__visual">
      <origin rpy="0  0  0" xyz="0.048  0    -0.03"/>
      <geometry>
        <cylinder length="0.158" radius="0.045"/>
      </geometry>
    </visual>
  </link>
  <link name="myArm__MittleresGelenk1">
    <inertial>
      <mass value="5.27"/>
      <origin rpy="0  0  0" xyz="0  0  0"/>
      <inertia ixx="1.89583" ixy="0" ixz="0" iyy="1.89583" iyz="0" izz="1.625"/>
    </inertial>
    <collision name="myArm__collision">
      <origin rpy="2.44361  1.57078  2.44361" xyz="0  0  0"/>
      <geometry>
        <cylinder length="0.152" radius="0.065"/>
      </geometry>
    </collision>
    <visual name="myArm__visual">
      <origin rpy="2.44361  1.57078  2.44361" xyz="0  0  0"/>
      <geometry>
        <cylinder length="0.152" radius="0.065"/>
      </geometry>
    </visual>
  </link>
  <link name="myArm__MittleresGelenk2">
    <inertial>
      <mass value="5.27"/>
      <origin rpy="0  0  0" xyz="0  0  0"/>
      <inertia ixx="1.89583" ixy="0" ixz="0" iyy="1.89583" iyz="0" izz="1.625"/>
    </inertial>
    <collision name="myArm__collision">
      <origin rpy="0  0  0" xyz="0  0  0"/>
      <geometry>
        <cylinder length="0.152" radius="0.065"/>
      </geometry>
    </collision>
    <visual name="myArm__visual">
      <origin rpy="0  0  0" xyz="0  0  0"/>
      <geometry>
        <cylinder length="0.152" radius="0.065"/>
      </geometry>
    </visual>
  </link>
  <link name="myArm__Oberschwinge">
    <inertial>
      <mass value="1.62"/>
      <origin rpy="0  0  0" xyz="0  0  0"/>
      <inertia ixx="0.0329037" ixy="0" ixz="0" iyy="0.0329037" iyz="0" izz="0.00164025"/>
    </inertial>
    <collision name="myArm__collision">
      <origin rpy="0  0  0" xyz="0  0  0"/>
      <geometry>
        <cylinder length="0.4875" radius="0.045"/>
      </geometry>
    </collision>
    <visual name="myArm__visual">
      <origin rpy="0  0  0" xyz="0  0  0"/>
      <geometry>
        <cylinder length="0.4875" radius="0.045"/>
      </geometry>
    </visual>
  </link>
  <link name="myArm__Unterschwinge">
    <inertial>
      <mass value="3.395"/>
      <origin rpy="0  0  0" xyz="0  0  0"/>
      <inertia ixx="0.495104" ixy="0" ixz="0" iyy="0.495104" iyz="0" izz="0.424375"/>
    </inertial>
    <collision name="myArm__collision">
      <origin rpy="0  0  0" xyz="0  0  0"/>
      <geometry>
        <cylinder length="0.542" radius="0.06"/>
      </geometry>
    </collision>
    <visual name="myArm__visual">
      <origin rpy="0  0  0" xyz="0  0  0"/>
      <geometry>
        <cylinder length="0.542" radius="0.06"/>
      </geometry>
    </visual>
  </link>
  <link name="myArm__left_finger">
    <inertial>
      <mass value="0.25"/>
      <origin rpy="0  0  0" xyz="0  0  0"/>
      <inertia ixx="0.00083542" ixy="0" ixz="0" iyy="0.00118542" iyz="0" izz="0.00035417"/>
    </inertial>
    <collision name="myArm__collision">
      <origin rpy="0  0  0" xyz="0  0  0"/>
      <geometry>
        <box size="0.07 0.002 0.1"/>
      </geometry>
    </collision>
    <visual name="myArm__visual">
      <origin rpy="0  0  0" xyz="0  0  0"/>
      <geometry>
        <box size="0.07 0.002 0.1"/>
      </geometry>
    </visual>
  </link>
  <link name="myArm__palm">
    <inertial>
      <mass value="0.5"/>
      <origin rpy="0  0  0" xyz="0  0  0"/>
      <inertia ixx="0.00095417" ixy="0" ixz="0" iyy="0.00022083" iyz="0" izz="0.00114167"/>
    </inertial>
    <collision name="myArm__collision">
      <origin rpy="0  0  0" xyz="0  0  0"/>
      <geometry>
        <box size="0.07 0.15 0.02"/>
      </geometry>
    </collision>
    <visual name="myArm__visual">
      <origin rpy="0  0  0" xyz="0  0  0"/>
      <geometry>
        <box size="0.07 0.15 0.02"/>
      </geometry>
    </visual>
  </link>
  <link name="myArm__right_finger">
    <inertial>
      <mass value="0.25"/>
      <origin rpy="0  0  0" xyz="0  0  0"/>
      <inertia ixx="0.00083542" ixy="0" ixz="0" iyy="0.00118542" iyz="0" izz="0.00035417"/>
    </inertial>
    <collision name="myArm__collision">
      <origin rpy="0  0  0" xyz="0  0  0"/>
      <geometry>
        <box size="0.07 0.002 0.1"/>
      </geometry>
    </collision>
    <visual name="myArm__visual">
      <origin rpy="0  0  0" xyz="0  0  0"/>
      <geometry>
        <box size="0.07 0.002 0.1"/>
      </geometry>
    </visual>
  </link>
</robot>
